INFO:__main__:Starting MyCobot Remote MCP HTTP Server
INFO:__main__:HTTP Server: 127.0.0.1:8082
INFO:__main__:API Server: localhost:8080
INFO:mycobot_mcp_lib:Connected to MyCobot API server at http://localhost:8080
INFO:mycobot_mcp_lib:Robot connected: True
INFO:__main__:============================================================
INFO:__main__:MyCobot Remote MCP Server Started!
INFO:__main__:============================================================
INFO:__main__:üåê HTTP Server: http://127.0.0.1:8082
INFO:__main__:üîå SSE Endpoint: http://127.0.0.1:8082/sse
INFO:__main__:‚ù§Ô∏è  Health Check: http://127.0.0.1:8082/health
INFO:__main__:üìã MCP Spec: http://127.0.0.1:8082/mcp
INFO:__main__:ü§ñ API Server: http://localhost:8080
INFO:__main__:============================================================
INFO:__main__:üéØ Ready for ChatGPT Remote MCP connections!
INFO:__main__:üí° Add this URL to ChatGPT: http://127.0.0.1:8082/sse
INFO:__main__:============================================================
ERROR:aiohttp.server:Error handling request from 127.0.0.1
Traceback (most recent call last):
  File "/home/factory/arms/.venv/lib/python3.11/site-packages/aiohttp/web_protocol.py", line 510, in _handle_request
    resp = await request_handler(request)
           ^^^^^^^^^^^^^^^^^^^^^^^^^^^^^^
  File "/home/factory/arms/.venv/lib/python3.11/site-packages/aiohttp/web_app.py", line 569, in _handle
    return await handler(request)
           ^^^^^^^^^^^^^^^^^^^^^^
  File "/home/factory/arms/.venv/lib/python3.11/site-packages/aiohttp/web_middlewares.py", line 117, in impl
    return await handler(request)
                 ^^^^^^^^^^^^^^^^
TypeError: 'Response' object is not callable
INFO:aiohttp.access:127.0.0.1 [03/Aug/2025:19:18:56 +0900] "GET / HTTP/1.1" 500 247 "-" "curl/7.88.1"
